2018-03-19 12:53:40,961 ERROR: Exception on /reset_password_request [POST] [in c:\users\user\fchronon\venv\lib\site-packages\flask\app.py:1560]
Traceback (most recent call last):
  File "c:\users\user\fchronon\venv\lib\site-packages\flask\app.py", line 1982, in wsgi_app
    response = self.full_dispatch_request()
  File "c:\users\user\fchronon\venv\lib\site-packages\flask\app.py", line 1614, in full_dispatch_request
    rv = self.handle_user_exception(e)
  File "c:\users\user\fchronon\venv\lib\site-packages\flask\app.py", line 1517, in handle_user_exception
    reraise(exc_type, exc_value, tb)
  File "c:\users\user\fchronon\venv\lib\site-packages\flask\_compat.py", line 33, in reraise
    raise value
  File "c:\users\user\fchronon\venv\lib\site-packages\flask\app.py", line 1612, in full_dispatch_request
    rv = self.dispatch_request()
  File "c:\users\user\fchronon\venv\lib\site-packages\flask\app.py", line 1598, in dispatch_request
    return self.view_functions[rule.endpoint](**req.view_args)
  File "C:\Users\user\fchronon\app\routes.py", line 151, in reset_password_request
    send_password_reset_email(user)
  File "C:\Users\user\fchronon\app\email.py", line 17, in send_password_reset_email
    html_body=render_template('email/reset_password.html', user=user, token=token))
  File "C:\Users\user\fchronon\app\email.py", line 9, in send_email
    mail.send(msg)
  File "c:\users\user\fchronon\venv\lib\site-packages\flask_mail.py", line 491, in send
    with self.connect() as connection:
  File "c:\users\user\fchronon\venv\lib\site-packages\flask_mail.py", line 144, in __enter__
    self.host = self.configure_host()
  File "c:\users\user\fchronon\venv\lib\site-packages\flask_mail.py", line 165, in configure_host
    host.login(self.mail.username, self.mail.password)
  File "C:\Program Files\Python36\lib\smtplib.py", line 729, in login
    raise last_exception
  File "C:\Program Files\Python36\lib\smtplib.py", line 720, in login
    initial_response_ok=initial_response_ok)
  File "C:\Program Files\Python36\lib\smtplib.py", line 641, in auth
    raise SMTPAuthenticationError(code, resp)
smtplib.SMTPAuthenticationError: (535, b'5.7.8 Username and Password not accepted. Learn more at\n5.7.8  https://support.google.com/mail/?p=BadCredentials k23sm2172104ljg.60 - gsmtp')
2018-03-19 12:59:11,262 INFO: Microblog startup [in C:\Users\user\fchronon\app\__init__.py:45]
2018-03-19 14:58:55,839 INFO: Microblog startup [in C:\Users\user\fchronon\app\__init__.py:45]
2018-03-19 15:14:05,600 INFO: Microblog startup [in C:\Users\user\fchronon\app\__init__.py:47]
2018-03-20 22:57:12,973 INFO: Microblog startup [in C:\Users\user\fchronon\app\__init__.py:49]
2018-03-20 23:04:34,483 INFO: Microblog startup [in C:\Users\user\fchronon\app\__init__.py:49]
