2018-03-17 16:26:22,421 INFO: Microblog startup [in C:\Users\user\fchronon\app\__init__.py:43]
2018-03-17 16:35:49,793 INFO: Microblog startup [in C:\Users\user\fchronon\app\__init__.py:43]
2018-03-18 09:19:55,426 INFO: Microblog startup [in C:\Users\user\fchronon\app\__init__.py:43]
2018-03-18 09:21:34,204 INFO: Microblog startup [in C:\Users\user\fchronon\app\__init__.py:43]
2018-03-18 09:23:09,339 INFO: Microblog startup [in C:\Users\user\fchronon\app\__init__.py:43]
2018-03-18 09:23:29,811 INFO: Microblog startup [in C:\Users\user\fchronon\app\__init__.py:43]
2018-03-18 13:25:42,567 INFO: Microblog startup [in C:\Users\user\fchronon\app\__init__.py:43]
2018-03-18 13:30:14,757 INFO: Microblog startup [in C:\Users\user\fchronon\app\__init__.py:43]
2018-03-18 13:46:48,353 INFO: Microblog startup [in C:\Users\user\fchronon\app\__init__.py:43]
2018-03-18 13:47:13,323 INFO: Microblog startup [in C:\Users\user\fchronon\app\__init__.py:43]
2018-03-18 23:26:17,351 INFO: Microblog startup [in C:\Users\user\fchronon\app\__init__.py:43]
2018-03-18 23:41:03,253 INFO: Microblog startup [in C:\Users\user\fchronon\app\__init__.py:43]
2018-03-19 00:02:19,114 INFO: Microblog startup [in C:\Users\user\fchronon\app\__init__.py:43]
2018-03-19 00:02:21,549 ERROR: Exception on /index [GET] [in c:\users\user\fchronon\venv\lib\site-packages\flask\app.py:1560]
Traceback (most recent call last):
  File "c:\users\user\fchronon\venv\lib\site-packages\flask\app.py", line 1982, in wsgi_app
    response = self.full_dispatch_request()
  File "c:\users\user\fchronon\venv\lib\site-packages\flask\app.py", line 1614, in full_dispatch_request
    rv = self.handle_user_exception(e)
  File "c:\users\user\fchronon\venv\lib\site-packages\flask\app.py", line 1517, in handle_user_exception
    reraise(exc_type, exc_value, tb)
  File "c:\users\user\fchronon\venv\lib\site-packages\flask\_compat.py", line 33, in reraise
    raise value
  File "c:\users\user\fchronon\venv\lib\site-packages\flask\app.py", line 1612, in full_dispatch_request
    rv = self.dispatch_request()
  File "c:\users\user\fchronon\venv\lib\site-packages\flask\app.py", line 1598, in dispatch_request
    return self.view_functions[rule.endpoint](**req.view_args)
  File "c:\users\user\fchronon\venv\lib\site-packages\flask_login\utils.py", line 261, in decorated_view
    return func(*args, **kwargs)
  File "C:\Users\user\fchronon\app\routes.py", line 28, in index
    posts = current_user.followed_posts().paginate(page, app.config['POST_PER_PAGE'], False)
KeyError: 'POST_PER_PAGE'
2018-03-19 00:02:27,626 ERROR: Exception on /index [GET] [in c:\users\user\fchronon\venv\lib\site-packages\flask\app.py:1560]
Traceback (most recent call last):
  File "c:\users\user\fchronon\venv\lib\site-packages\flask\app.py", line 1982, in wsgi_app
    response = self.full_dispatch_request()
  File "c:\users\user\fchronon\venv\lib\site-packages\flask\app.py", line 1614, in full_dispatch_request
    rv = self.handle_user_exception(e)
  File "c:\users\user\fchronon\venv\lib\site-packages\flask\app.py", line 1517, in handle_user_exception
    reraise(exc_type, exc_value, tb)
  File "c:\users\user\fchronon\venv\lib\site-packages\flask\_compat.py", line 33, in reraise
    raise value
  File "c:\users\user\fchronon\venv\lib\site-packages\flask\app.py", line 1612, in full_dispatch_request
    rv = self.dispatch_request()
  File "c:\users\user\fchronon\venv\lib\site-packages\flask\app.py", line 1598, in dispatch_request
    return self.view_functions[rule.endpoint](**req.view_args)
  File "c:\users\user\fchronon\venv\lib\site-packages\flask_login\utils.py", line 261, in decorated_view
    return func(*args, **kwargs)
  File "C:\Users\user\fchronon\app\routes.py", line 28, in index
    posts = current_user.followed_posts().paginate(page, app.config['POST_PER_PAGE'], False)
KeyError: 'POST_PER_PAGE'
2018-03-19 00:02:43,234 ERROR: Exception on /index [GET] [in c:\users\user\fchronon\venv\lib\site-packages\flask\app.py:1560]
Traceback (most recent call last):
  File "c:\users\user\fchronon\venv\lib\site-packages\flask\app.py", line 1982, in wsgi_app
    response = self.full_dispatch_request()
  File "c:\users\user\fchronon\venv\lib\site-packages\flask\app.py", line 1614, in full_dispatch_request
    rv = self.handle_user_exception(e)
  File "c:\users\user\fchronon\venv\lib\site-packages\flask\app.py", line 1517, in handle_user_exception
    reraise(exc_type, exc_value, tb)
  File "c:\users\user\fchronon\venv\lib\site-packages\flask\_compat.py", line 33, in reraise
    raise value
  File "c:\users\user\fchronon\venv\lib\site-packages\flask\app.py", line 1612, in full_dispatch_request
    rv = self.dispatch_request()
  File "c:\users\user\fchronon\venv\lib\site-packages\flask\app.py", line 1598, in dispatch_request
    return self.view_functions[rule.endpoint](**req.view_args)
  File "c:\users\user\fchronon\venv\lib\site-packages\flask_login\utils.py", line 261, in decorated_view
    return func(*args, **kwargs)
  File "C:\Users\user\fchronon\app\routes.py", line 28, in index
    posts = current_user.followed_posts().paginate(page, app.config['POST_PER_PAGE'], False)
KeyError: 'POST_PER_PAGE'
2018-03-19 00:03:36,070 INFO: Microblog startup [in C:\Users\user\fchronon\app\__init__.py:43]
2018-03-19 00:09:02,959 INFO: Microblog startup [in C:\Users\user\fchronon\app\__init__.py:43]
2018-03-19 00:10:26,379 INFO: Microblog startup [in C:\Users\user\fchronon\app\__init__.py:43]
2018-03-19 00:39:58,461 INFO: Microblog startup [in C:\Users\user\fchronon\app\__init__.py:45]
2018-03-19 12:46:40,168 INFO: Microblog startup [in C:\Users\user\fchronon\app\__init__.py:45]
2018-03-19 12:49:03,596 ERROR: Exception on /reset_password_request [POST] [in c:\users\user\fchronon\venv\lib\site-packages\flask\app.py:1560]
Traceback (most recent call last):
  File "c:\users\user\fchronon\venv\lib\site-packages\flask\app.py", line 1982, in wsgi_app
    response = self.full_dispatch_request()
  File "c:\users\user\fchronon\venv\lib\site-packages\flask\app.py", line 1614, in full_dispatch_request
    rv = self.handle_user_exception(e)
  File "c:\users\user\fchronon\venv\lib\site-packages\flask\app.py", line 1517, in handle_user_exception
    reraise(exc_type, exc_value, tb)
  File "c:\users\user\fchronon\venv\lib\site-packages\flask\_compat.py", line 33, in reraise
    raise value
  File "c:\users\user\fchronon\venv\lib\site-packages\flask\app.py", line 1612, in full_dispatch_request
    rv = self.dispatch_request()
  File "c:\users\user\fchronon\venv\lib\site-packages\flask\app.py", line 1598, in dispatch_request
    return self.view_functions[rule.endpoint](**req.view_args)
  File "C:\Users\user\fchronon\app\routes.py", line 151, in reset_password_request
    send_password_reset_email(user)
  File "C:\Users\user\fchronon\app\email.py", line 17, in send_password_reset_email
    html_body=render_template('email/reset_password.html', user=user, token=token))
  File "C:\Users\user\fchronon\app\email.py", line 9, in send_email
    mail.send(msg)
  File "c:\users\user\fchronon\venv\lib\site-packages\flask_mail.py", line 491, in send
    with self.connect() as connection:
  File "c:\users\user\fchronon\venv\lib\site-packages\flask_mail.py", line 144, in __enter__
    self.host = self.configure_host()
  File "c:\users\user\fchronon\venv\lib\site-packages\flask_mail.py", line 165, in configure_host
    host.login(self.mail.username, self.mail.password)
  File "C:\Program Files\Python36\lib\smtplib.py", line 729, in login
    raise last_exception
  File "C:\Program Files\Python36\lib\smtplib.py", line 720, in login
    initial_response_ok=initial_response_ok)
  File "C:\Program Files\Python36\lib\smtplib.py", line 641, in auth
    raise SMTPAuthenticationError(code, resp)
smtplib.SMTPAuthenticationError: (535, b'5.7.8 Username and Password not accepted. Learn more at\n5.7.8  https://support.google.com/mail/?p=BadCredentials f26-v6sm1775614lfl.83 - gsmtp')
